bot.py[LINE:311]#ERROR    [2016-12-19 11:59:04,504] error: <class 'requests.exceptions.ConnectionError'>
